Workbook

Sheet Notes for Use
A1: Cash Flow Forecasting can be one of the most effective tools in a small businesses financial toolbelt!
A2: If you don't love Excel, no worries. We built this for anyone to use, not just Excel nerds like us.
A4: What this document is:
A5: 1) An additional way to look at and predict what your business finances can look like in the future
A6: 2) A tool to use in helping you make decisions
A7: 3) Supposed to be tested, manipulated, and modified
A8: 4) Meant to be an approximation of what could happen in the future if certain decisions are made/not made
A9: 5) Something that you may want to look over with a business partner, financial adviser, CFO, CPA, or Business Coach for additional input
A10: 6) Something that you review regularly based on what makes sense to your business operations.
A12: What this document is not:
A13: 1) A financial statement - this is not telling you historical fact, it's used to estimate the future
A14: 2) A document you send to your banker or used to apply for a loan.
... A22: 4) Please reach out to us with any questions regarding this document: hello@claracfo.com

Sheet Video Instructions

Sheet Cash Rhythms
A1: Cash Rhythms: | C1: Note: If you want to change the drop down list options for "Cadence", unhide column H and edit options
B2: Video Explaining here: | C2: https://youtu.be/8S1EBcJ3pXo
H3: mulitple times per day
H4: once per day
B5: Incoming Cash | C5: Cadence | D5: Day | E5: Acceleration Action | H5: weekly
A6: 1 | H6: semi-monthly (24x per year)
A7: 2 | H7: bi-weekly (26x per year)
A8: 3 | H8: Monthly
A9: 4 | H9: Quarterly
A10: 5 | H10: Annual
A11: 6 | H11: Ad Hoc
A12: 7 | H12: Other
A13: 8
A14: 9
A15: 10
B17: Outgoing Cash | C17: Cadence | D17: Day | E17: Deceleration Action
A18: 1
A19: 2
A20: 3
A21: 4
A22: 5
A23: 6
A24: 7
A25: 8
A26: 9
A27: 10
A28: 11
A29: 12
... A47: 30

Sheet Cash Flow Forecast 
B3: Budget/Cash Flow
C5: Period (Month): | D5: 45955 | E5: =+D5+31 -> 45986 | F5: =+E5+30 -> 46016 | G5: =+F5+30 -> 46046 | H5: =+G5+30 -> 46076 | I5: =+H5+30 -> 46106 | J5: =+I5+30 -> 46136 | K5: =+J5+31 -> 46167 | L5: =+K5+30 -> 46197 | M5: =+L5+31 -> 46228 | N5: =+M5+30 -> 46258 | O5: =+N5+31 -> 46289 | P5: Year 1 | R5: =+D5+365 -> 46320 | S5: =+E5+365 -> 46351 | T5: =+F5+365 -> 46381 | U5: =+G5+365 -> 46411 | V5: =+H5+365 -> 46441 | W5: =+I5+365 -> 46471 | X5: =+J5+365 -> 46501 | Y5: =+K5+365 -> 46532 | ... AC5: =+O5+365 -> 46654
A6: Cash at the Beginning of the period | D6: 0 | E6: =D74 -> 9778.75 | F6: =E74 -> 7779 | G6: =F74 -> 6875.25 | H6: =G74 -> 8940.5 | I6: =H74 -> 7355.75 | J6: =I74 -> 9971 | K6: =J74 -> 8936.25 | L6: =K74 -> 6851.5 | ... O6: =N74 -> 8647.25 | R6: =O74 -> 7062.5 | S6: =R74 -> 7062.5 | T6: =S74 -> #REF! | U6: =T74 -> #REF! | V6: =U74 -> #REF! | W6: =V74 -> #REF! | X6: =W74 -> #REF! | Y6: =X74 -> #REF! | Z6: =Y74 -> #REF! | ... AC6: =AB74 -> #REF!
A8: Income Sources (CASH IN)
B9: Mentor Donations | D9: 13000 | E9: 2000 | F9: 2000 | G9: 1000 | H9: 1000 | I9: 1000 | J9: 1000 | K9: 1000 | L9: 1000 | M9: 1000 | N9: 1000 | O9: 1000 | P9: =SUM(D9:O9) -> 26000
B10: Clients | D10: 250 | E10: 250 | F10: =+E10 -> 250 | G10: =+F10 -> 250 | H10: =+G10 -> 250 | I10: =+H10 -> 250 | J10: =+I10 -> 250 | K10: =+J10 -> 250 | L10: =+K10 -> 250 | M10: =+L10 -> 250 | ... O10: =+N10 -> 250 | P10: =SUM(D10:O10) -> 3000
B11: Workshop Sponsorship/Fees | G11: 4400 | H11: 100 | I11: 5000 | J11: 100 | K11: 100 | L11: 100 | M11: 5000 | N11: 100 | O11: 100 | P11: =SUM(D11:O11) -> 15000
B12: Corporate Sponsorships | H12: 1000 | J12: 1000 | L12: 1000 | N12: 1000 | P12: =SUM(D12:O12) -> 4000
B13: Grants | E13: 0 | M13: 1000 | O13: 1000 | P13: =SUM(D13:O13) -> 2000
A14: Total Income: | D14: =SUM(D9:D13) -> 13250 | E14: =SUM(E9:E13) -> 2250 | F14: =SUM(F9:F13) -> 2250 | G14: =SUM(G9:G13) -> 5650 | H14: =SUM(H9:H13) -> 2350 | I14: =SUM(I9:I13) -> 6250 | J14: =SUM(J9:J13) -> 2350 | K14: =SUM(K9:K13) -> 1350 | ... P14: =SUM(P9:P13) -> 50000 | R14: =SUM(R9:R13) -> 0 | S14: =SUM(#REF!) -> #REF! | T14: =SUM(#REF!) -> #REF! | U14: =SUM(#REF!) -> #REF! | V14: =SUM(#REF!) -> #REF! | W14: =SUM(#REF!) -> #REF! | X14: =SUM(#REF!) -> #REF! | Y14: =SUM(#REF!) -> #REF! | Z14: =SUM(#REF!) -> #REF! | ... AC14: =SUM(#REF!) -> #REF!
A16: Expenses | AG16: fa
A18: Programs
B19: Workshops | F19: 50 | G19: =+F19 -> 50 | H19: =+G19 -> 50 | I19: =+H19 -> 50 | J19: =+I19 -> 50 | K19: =+J19 -> 50 | L19: =+K19 -> 50 | M19: =+L19 -> 50 | N19: =+M19 -> 50 | O19: =+N19 -> 50 | P19: =SUM(D19:O19) -> 500
B20: Constant Contact | E20: 50 | F20: =+E20 -> 50 | G20: =+F20 -> 50 | H20: =+G20 -> 50 | I20: =+H20 -> 50 | J20: =+I20 -> 50 | K20: =+J20 -> 50 | L20: =+K20 -> 50 | M20: =+L20 -> 50 | ... O20: =+N20 -> 50 | P20: =SUM(D20:O20) -> 550
B21: Other | P21: =SUM(D21:O21) -> 0
A22: Total Programs | D22: =SUM(D19:D21) -> 0 | E22: =SUM(E19:E21) -> 50 | F22: =SUM(F19:F21) -> 100 | G22: =SUM(G19:G21) -> 100 | H22: =SUM(H19:H21) -> 100 | I22: =SUM(I19:I21) -> 100 | J22: =SUM(J19:J21) -> 100 | K22: =SUM(K19:K21) -> 100 | ... O22: =SUM(O19:O21) -> 100 | P22: =+P21+P19 -> 500
A24: Fundraising & Marketing
B25: Website | D25: =+IT!B4 -> 90 | E25: =+IT!C4 -> 30 | F25: =+IT!D4 -> 30 | G25: =+IT!E4 -> 30 | H25: =+IT!F4 -> 30 | I25: =+IT!G4 -> 30 | J25: =+IT!H4 -> 30 | K25: =+IT!I4 -> 30 | ... O25: =+IT!M4 -> 30 | P25: =SUM(D25:O25) -> 420
B26: Professional Fees (Fund Raising) | G26: 250 | J26: 250 | M26: 250 | P26: =SUM(D26:O26) -> 750
B27: Advertising & Social Media | E27: 150 | F27: =+E27 -> 150 | G27: =+F27 -> 150 | H27: =+G27 -> 150 | I27: =+H27 -> 150 | J27: =+I27 -> 150 | K27: =+J27 -> 150 | L27: =+K27 -> 150 | M27: =+L27 -> 150 | ... O27: =+N27 -> 150 | P27: =SUM(D27:O27) -> 1650
B28: Podcasts | H28: 500 | L28: 500 | P28: =SUM(D28:O28) -> 1000
B29: Conferences | I29: 500 | O29: 500 | P29: =SUM(D29:O29) -> 1000
B30: Travel | E30: 50 | F30: =+E30 -> 50 | G30: =+F30 -> 50 | H30: =+G30 -> 50 | I30: =+H30 -> 50 | J30: =+I30 -> 50 | K30: =+J30 -> 50 | L30: =+K30 -> 50 | M30: =+L30 -> 50 | ... O30: =+N30 -> 50 | P30: =SUM(D30:O30) -> 550
A31: Total Fundraising and Marketing | D31: =SUM(D25:D30) -> 90 | E31: =SUM(E25:E30) -> 230 | F31: =SUM(F25:F30) -> 230 | G31: =SUM(G25:G30) -> 480 | H31: =SUM(H25:H30) -> 730 | I31: =SUM(I25:I30) -> 730 | J31: =SUM(J25:J30) -> 480 | K31: =SUM(K25:K30) -> 230 | ... AC31: =SUM(AC25:AC30) -> 0
A33: Technology
B34: CRM System | C34: Hubspot | D34: 75 | E34: 75 | F34: =+E34 -> 75 | G34: =+F34 -> 75 | H34: =+G34 -> 75 | I34: =+H34 -> 75 | J34: =+I34 -> 75 | K34: =+J34 -> 75 | L34: =+K34 -> 75 | M34: =+L34 -> 75 | ... O34: =+N34 -> 75 | P34: =SUM(D34:O34) -> 900
B35: Telecomunications-Zoom | D35: 90 | E35: 766 | G35: =+F35 -> 0 | H35: =+G35 -> 0 | I35: =+H35 -> 0 | J35: =+I35 -> 0 | K35: =+J35 -> 0 | L35: =+K35 -> 0 | M35: =+L35 -> 0 | N35: =+M35 -> 0 | O35: =+N35 -> 0 | P35: =SUM(D35:O35) -> 856
B36: Google Workspace | D36: =27*16 -> 432 | E36: 50 | F36: 50 | G36: 50 | H36: 50 | I36: 50 | J36: 50 | K36: 50 | L36: 50 | M36: 50 | N36: 50 | O36: 50 | P36: =SUM(D36:O36) -> 982
B37: Other | D37: 100 | E37: 100 | F37: =+E37 -> 100 | G37: =+F37 -> 100 | H37: =+G37 -> 100 | I37: =+H37 -> 100 | J37: =+I37 -> 100 | K37: =+J37 -> 100 | L37: =+K37 -> 100 | M37: =+L37 -> 100 | ... O37: =+N37 -> 100 | P37: =SUM(D37:O37) -> 1200
A38: Total Technology | D38: =SUM(D34:D37) -> 697 | E38: =SUM(E34:E37) -> 991 | F38: =SUM(F34:F37) -> 225 | G38: =SUM(G34:G37) -> 225 | H38: =SUM(H34:H37) -> 225 | I38: =SUM(I34:I37) -> 225 | J38: =SUM(J34:J37) -> 225 | K38: =SUM(K34:K37) -> 225 | ... P38: =SUM(P34:P37) -> 3938
A40: Administration & Overhead
B41: Payroll | D41: 1200 | E41: 2400 | F41: =+E41 -> 2400 | G41: =+F41 -> 2400 | H41: =+G41 -> 2400 | I41: =+H41 -> 2400 | J41: =+I41 -> 2400 | K41: =+J41 -> 2400 | L41: =+K41 -> 2400 | M41: =+L41 -> 2400 | ... O41: =+N41 -> 2400 | P41: =SUM(D41:O41) -> 27600
B42: Payroll taxes | P42: =SUM(D42:O42) -> 0
B43: QB& Tax Prep | E43: 80 | G43: 200 | J43: =+I43 -> 0 | K43: =+J43 -> 0 | L43: =+K43 -> 0 | M43: =+L43 -> 0 | N43: =+M43 -> 0 | O43: =+N43 -> 0 | P43: =SUM(D43:O43) -> 280 | Q43: 1 | R43: =+O43 -> 0
B44: Office Expense | D44: 0 | E44: 50 | F44: =+E44 -> 50 | G44: =+F44 -> 50 | H44: =+G44 -> 50 | I44: =+H44 -> 50 | J44: =+I44 -> 50 | K44: =+J44 -> 50 | L44: =+K44 -> 50 | M44: =+L44 -> 50 | ... O44: =+N44 -> 50 | P44: =SUM(D44:O44) -> 550
B45: Insurance | D45: 100 | E45: =+D45 -> 100 | F45: =+E45 -> 100 | G45: =+F45 -> 100 | H45: =+G45 -> 100 | I45: =+H45 -> 100 | J45: =+I45 -> 100 | K45: =+J45 -> 100 | L45: =+K45 -> 100 | ... O45: =+N45 -> 100 | P45: =SUM(D45:O45) -> 1200 | Q45: 1
B46: Meeting Expenses | E46: 300 | H46: 300 | K46: 300 | O46: 300 | P46: =SUM(D46:O46) -> 1200
B47: Legal and Startup | D47: 1000 | P47: =SUM(D47:O47) -> 1000 | Q47: 1
B48: Bank & CC Fees | D48: =0.029*(D9+D10) -> 384.25 | E48: =0.019*(E9+E10)+6 -> 48.75 | F48: =0.019*(F9+F10)+6 -> 48.75 | G48: =0.019*(G9+G10)+6 -> 29.75 | H48: =0.019*(H9+H10)+6 -> 29.75 | I48: =0.019*(I9+I10)+6 -> 29.75 | J48: =0.019*(J9+J10)+6 -> 29.75 | K48: =0.019*(K9+K10)+6 -> 29.75 | L48: =0.019*(L9+L10)+6 -> 29.75 | ... O48: =0.019*(O9+O10)+6 -> 29.75 | P48: =SUM(D48:O48) -> 749.5
A49: Total Admin & Overhead | D49: =SUM(D41:D48) -> 2684.25 | E49: =SUM(E41:E48) -> 2978.75 | F49: =SUM(F41:F48) -> 2598.75 | G49: =SUM(G41:G48) -> 2779.75 | H49: =SUM(H41:H48) -> 2879.75 | I49: =SUM(I41:I48) -> 2579.75 | J49: =SUM(J41:J48) -> 2579.75 | K49: =SUM(K41:K48) -> 2879.75 | ... P49: =SUM(P41:P48) -> 32579.5
...

Sheet Sheet1

Sheet Marketing
A3: Marketing | K3: I think we may have found a solution for a CRM platform at no charge, more to come.
K5: If we decide to hold in-person meetings the room usually runs ~ $150 and Beverly can tell you estimated costs for refreshments
K7: There may be some additional charges for anyone who wants business cards ($8 for 50 shipped to their address in about two weeks) or a name badge ($7 shipped to their address in about two weeks).
K9: Trade Show sign $64.
K11: Client Appreciation / Client of the Year Luncheon - $5,000?

Sheet IT
A2: IT | B2: 45955 | C2: =+B2+31 -> 45986 | D2: =+C2+30 -> 46016 | E2: =+D2+30 -> 46046 | F2: =+E2+30 -> 46076 | G2: =+F2+30 -> 46106 | H2: =+G2+30 -> 46136 | I2: =+H2+31 -> 46167 | J2: =+I2+30 -> 46197 | K2: =+J2+31 -> 46228 | L2: =+K2+30 -> 46258 | M2: =+L2+31 -> 46289 | N2: Year 1 | O2: # of Users
A4: Website | B4: 90 | C4: 30 | D4: =+C4 -> 30 | E4: =+D4 -> 30 | F4: =+E4 -> 30 | G4: =+F4 -> 30 | H4: =+G4 -> 30 | I4: =+H4 -> 30 | J4: =+I4 -> 30 | K4: =+J4 -> 30 | ... M4: =+L4 -> 30 | N4: =SUM(B4:M4) -> 420 | P4: $30/year domain registration for 2 domains $30/mo for website hosting
A5: GoogleWorkspace | B5: =18*10 -> 180 | C5: =18*25 -> 450 | E5: =+D5 -> 0 | F5: =+E5 -> 0 | G5: =+F5 -> 0 | H5: =+G5 -> 0 | I5: =+H5 -> 0 | J5: =+I5 -> 0 | K5: =+J5 -> 0 | L5: =+K5 -> 0 | M5: =+L5 -> 0 | N5: =SUM(B5:M5) -> 630 | O5: 10 | P5: $6/user/mo basic Google Workspace (may become free after we confirm tax exempt).
A6: Zoom | B6: 40 | C6: 40 | D6: 24 | E6: =+D6 -> 24 | F6: =+E6 -> 24 | G6: =+F6 -> 24 | H6: =+G6 -> 24 | I6: =+H6 -> 24 | J6: =+I6 -> 24 | K6: =+J6 -> 24 | L6: =+K6 -> 24 | M6: =+L6 -> 24 | N6: =SUM(B6:M6) -> 320 | O6: 2 | P6: $12/user/month Zoom license (if we decide to cover it).
B7: =SUM(B4:B6) -> 310 | C7: =SUM(C4:C6) -> 520 | D7: =SUM(D4:D6) -> 54 | E7: =SUM(E4:E6) -> 54 | F7: =SUM(F4:F6) -> 54 | G7: =SUM(G4:G6) -> 54 | H7: =SUM(H4:H6) -> 54 | I7: =SUM(I4:I6) -> 54 | ... N7: =SUM(N4:N6) -> 1370

Sheet 2025 Donors
A19: Mentor Donations
B20: Christine Gatti(150)
B21: Rich Impact Consulting (50)
B22: David Theran (150)
A24: Workshop Sponsorship
B25: Eastern Bank(3500)
B26: East Cambridge(5000)
B27: Middlesex(10,000)
B28: Fees
A31: Other Gifts & Grants
B32: Schwartz Foundation(1000)
B33: Urban Tech

Sheet Cash Flow Forecast - Personal
D9: 2024 | P9: 2025
C10: Period (Month): | D10: 45292 | E10: 45323 | F10: 45352 | G10: 45383 | H10: 45413 | I10: 45444 | J10: 45474 | K10: 45505 | L10: 45536 | M10: 45566 | N10: 45597 | O10: 45627 | P10: 45658 | Q10: 45689 | R10: 45717 | S10: 45748 | T10: 45778 | U10: 45809 | V10: 45839 | W10: 45870 | X10: 45901 | Y10: 45931 | Z10: 45962 | AA10: 45992
A11: Cash at the Beginning of the period | E11: =D59 -> 0 | F11: =E59 -> 0 | G11: =F59 -> 0 | H11: =G59 -> 0 | I11: =H59 -> 0 | J11: =I59 -> 0 | K11: =J59 -> 0 | L11: =K59 -> 0 | ... AA11: =Z59 -> 0
A14: Income Sources (CASH IN)
B15: Wages #1
B16: Wages #2
B17: Distributions/Draws
B18: Revenue Steam # 1
B19: Revenue Steam # 2
B20: Revenue Steam # 3
A21: Total Income: | D21: =SUM(D15:D20) -> 0 | E21: =SUM(E15:E20) -> 0 | F21: =SUM(F15:F20) -> 0 | G21: =SUM(G15:G20) -> 0 | H21: =SUM(H15:H20) -> 0 | I21: =SUM(I15:I20) -> 0 | J21: =SUM(J15:J20) -> 0 | K21: =SUM(K15:K20) -> 0 | ... AA21: =SUM(AA15:AA20) -> 0
A22: Expenses (CASH OUT)
B23: Mortgage/Rent
B24: Utilities
B25: Child Expenses
B26: Food
B27: Cell Phone
B28: Gas
B29: Healthcare
B30: Shopping
B31: Entertainment
B32: Pets
B33: Travel
B34: Misc
... B40: Expense #7
A41: Total Operating Expenses: | D41: =SUM(D23:D40) -> 0 | E41: =SUM(E23:E40) -> 0 | F41: =SUM(F23:F40) -> 0 | G41: =SUM(G23:G40) -> 0 | H41: =SUM(H23:H40) -> 0 | I41: =SUM(I23:I40) -> 0 | J41: =SUM(J23:J40) -> 0 | K41: =SUM(K23:K40) -> 0 | ... AA41: =SUM(AA23:AA40) -> 0
A42: Other Changes in Cash (CASH OUT)
B43: Loan #1
B44: Loan #2
B45: Loan #3
B46: Savings #1
B47: Savings #2
B48: Savings #3
A49: Other changes in cash out: | D49: =SUM(D43:D48) -> 0 | E49: =SUM(E43:E48) -> 0 | F49: =SUM(F43:F48) -> 0 | G49: =SUM(G43:G48) -> 0 | H49: =SUM(H43:H48) -> 0 | I49: =SUM(I43:I48) -> 0 | J49: =SUM(J43:J48) -> 0 | K49: =SUM(K43:K48) -> 0 | ... AA49: =SUM(AA43:AA48) -> 0
A50: Other Changes in Cash (CASH IN)
B51: Cash Received from Loan
B52: Cash received from investment
B53: Other #1
B54: Other #2
A55: Other changes in cash in: | D55: =SUM(D51:D54) -> 0 | E55: =SUM(E51:E54) -> 0 | F55: =SUM(F51:F54) -> 0 | G55: =SUM(G51:G54) -> 0 | H55: =SUM(H51:H54) -> 0 | I55: =SUM(I51:I54) -> 0 | J55: =SUM(J51:J54) -> 0 | K55: =SUM(K51:K54) -> 0 | ... AA55: =SUM(AA51:AA54) -> 0
...
